2025-10-16 11:24:04,803 - __main__ - ERROR - Connection failed: [Errno 8] nodename nor servname provided, or not known
2025-10-16 11:27:12,948 - __main__ - ERROR - Connection failed: BaseEventLoop.create_connection() got an unexpected keyword argument 'extra_headers'
Traceback (most recent call last):
  File "/Users/cicerojacobi/CascadeProjects/paradex_lik_dash/paradex_monitor/src/paradex_monitor.py", line 49, in connect
    self.websocket = await asyncio.wait_for(
                     ^^^^^^^^^^^^^^^^^^^^^^^
    ...<8 lines>...
    )
    ^
  File "/opt/homebrew/Cellar/python@3.13/3.13.7/Frameworks/Python.framework/Versions/3.13/lib/python3.13/asyncio/tasks.py", line 507, in wait_for
    return await fut
           ^^^^^^^^^
  File "/Users/cicerojacobi/CascadeProjects/paradex_lik_dash/paradex_monitor/.venv/lib/python3.13/site-packages/websockets/asyncio/client.py", line 541, in __await_impl__
    self.connection = await self.create_connection()
                      ^^^^^^^^^^^^^^^^^^^^^^^^^^^^^^
  File "/Users/cicerojacobi/CascadeProjects/paradex_lik_dash/paradex_monitor/.venv/lib/python3.13/site-packages/websockets/asyncio/client.py", line 467, in create_connection
    _, connection = await loop.create_connection(factory, **kwargs)
                          ~~~~~~~~~~~~~~~~~~~~~~^^^^^^^^^^^^^^^^^^^
TypeError: BaseEventLoop.create_connection() got an unexpected keyword argument 'extra_headers'
2025-10-16 11:27:20,728 - __main__ - ERROR - Connection failed: [Errno 8] nodename nor servname provided, or not known
Traceback (most recent call last):
  File "/Users/cicerojacobi/CascadeProjects/paradex_lik_dash/paradex_monitor/src/paradex_monitor.py", line 49, in connect
    self.websocket = await asyncio.wait_for(
                     ^^^^^^^^^^^^^^^^^^^^^^^
    ...<7 lines>...
    )
    ^
  File "/opt/homebrew/Cellar/python@3.13/3.13.7/Frameworks/Python.framework/Versions/3.13/lib/python3.13/asyncio/tasks.py", line 507, in wait_for
    return await fut
           ^^^^^^^^^
  File "/Users/cicerojacobi/CascadeProjects/paradex_lik_dash/paradex_monitor/.venv/lib/python3.13/site-packages/websockets/asyncio/client.py", line 541, in __await_impl__
    self.connection = await self.create_connection()
                      ^^^^^^^^^^^^^^^^^^^^^^^^^^^^^^
  File "/Users/cicerojacobi/CascadeProjects/paradex_lik_dash/paradex_monitor/.venv/lib/python3.13/site-packages/websockets/asyncio/client.py", line 467, in create_connection
    _, connection = await loop.create_connection(factory, **kwargs)
                    ^^^^^^^^^^^^^^^^^^^^^^^^^^^^^^^^^^^^^^^^^^^^^^^
  File "/opt/homebrew/Cellar/python@3.13/3.13.7/Frameworks/Python.framework/Versions/3.13/lib/python3.13/asyncio/base_events.py", line 1122, in create_connection
    infos = await self._ensure_resolved(
            ^^^^^^^^^^^^^^^^^^^^^^^^^^^^
        (host, port), family=family,
        ^^^^^^^^^^^^^^^^^^^^^^^^^^^^
        type=socket.SOCK_STREAM, proto=proto, flags=flags, loop=self)
        ^^^^^^^^^^^^^^^^^^^^^^^^^^^^^^^^^^^^^^^^^^^^^^^^^^^^^^^^^^^^^
  File "/opt/homebrew/Cellar/python@3.13/3.13.7/Frameworks/Python.framework/Versions/3.13/lib/python3.13/asyncio/base_events.py", line 1508, in _ensure_resolved
    return await loop.getaddrinfo(host, port, family=family, type=type,
           ^^^^^^^^^^^^^^^^^^^^^^^^^^^^^^^^^^^^^^^^^^^^^^^^^^^^^^^^^^^^
                                  proto=proto, flags=flags)
                                  ^^^^^^^^^^^^^^^^^^^^^^^^^
  File "/opt/homebrew/Cellar/python@3.13/3.13.7/Frameworks/Python.framework/Versions/3.13/lib/python3.13/asyncio/base_events.py", line 939, in getaddrinfo
    return await self.run_in_executor(
           ^^^^^^^^^^^^^^^^^^^^^^^^^^^
        None, getaddr_func, host, port, family, type, proto, flags)
        ^^^^^^^^^^^^^^^^^^^^^^^^^^^^^^^^^^^^^^^^^^^^^^^^^^^^^^^^^^^
  File "/opt/homebrew/Cellar/python@3.13/3.13.7/Frameworks/Python.framework/Versions/3.13/lib/python3.13/concurrent/futures/thread.py", line 59, in run
    result = self.fn(*self.args, **self.kwargs)
  File "/opt/homebrew/Cellar/python@3.13/3.13.7/Frameworks/Python.framework/Versions/3.13/lib/python3.13/socket.py", line 977, in getaddrinfo
    for res in _socket.getaddrinfo(host, port, family, type, proto, flags):
               ~~~~~~~~~~~~~~~~~~~^^^^^^^^^^^^^^^^^^^^^^^^^^^^^^^^^^^^^^^^
socket.gaierror: [Errno 8] nodename nor servname provided, or not known
2025-10-16 11:27:39,138 - __main__ - ERROR - Connection failed: [Errno 8] nodename nor servname provided, or not known
Traceback (most recent call last):
  File "/Users/cicerojacobi/CascadeProjects/paradex_lik_dash/paradex_monitor/src/paradex_monitor.py", line 49, in connect
    self.websocket = await asyncio.wait_for(
                     ^^^^^^^^^^^^^^^^^^^^^^^
    ...<7 lines>...
    )
    ^
  File "/opt/homebrew/Cellar/python@3.13/3.13.7/Frameworks/Python.framework/Versions/3.13/lib/python3.13/asyncio/tasks.py", line 507, in wait_for
    return await fut
           ^^^^^^^^^
  File "/Users/cicerojacobi/CascadeProjects/paradex_lik_dash/paradex_monitor/.venv/lib/python3.13/site-packages/websockets/asyncio/client.py", line 541, in __await_impl__
    self.connection = await self.create_connection()
                      ^^^^^^^^^^^^^^^^^^^^^^^^^^^^^^
  File "/Users/cicerojacobi/CascadeProjects/paradex_lik_dash/paradex_monitor/.venv/lib/python3.13/site-packages/websockets/asyncio/client.py", line 467, in create_connection
    _, connection = await loop.create_connection(factory, **kwargs)
                    ^^^^^^^^^^^^^^^^^^^^^^^^^^^^^^^^^^^^^^^^^^^^^^^
  File "/opt/homebrew/Cellar/python@3.13/3.13.7/Frameworks/Python.framework/Versions/3.13/lib/python3.13/asyncio/base_events.py", line 1122, in create_connection
    infos = await self._ensure_resolved(
            ^^^^^^^^^^^^^^^^^^^^^^^^^^^^
        (host, port), family=family,
        ^^^^^^^^^^^^^^^^^^^^^^^^^^^^
        type=socket.SOCK_STREAM, proto=proto, flags=flags, loop=self)
        ^^^^^^^^^^^^^^^^^^^^^^^^^^^^^^^^^^^^^^^^^^^^^^^^^^^^^^^^^^^^^
  File "/opt/homebrew/Cellar/python@3.13/3.13.7/Frameworks/Python.framework/Versions/3.13/lib/python3.13/asyncio/base_events.py", line 1508, in _ensure_resolved
    return await loop.getaddrinfo(host, port, family=family, type=type,
           ^^^^^^^^^^^^^^^^^^^^^^^^^^^^^^^^^^^^^^^^^^^^^^^^^^^^^^^^^^^^
                                  proto=proto, flags=flags)
                                  ^^^^^^^^^^^^^^^^^^^^^^^^^
  File "/opt/homebrew/Cellar/python@3.13/3.13.7/Frameworks/Python.framework/Versions/3.13/lib/python3.13/asyncio/base_events.py", line 939, in getaddrinfo
    return await self.run_in_executor(
           ^^^^^^^^^^^^^^^^^^^^^^^^^^^
        None, getaddr_func, host, port, family, type, proto, flags)
        ^^^^^^^^^^^^^^^^^^^^^^^^^^^^^^^^^^^^^^^^^^^^^^^^^^^^^^^^^^^
  File "/opt/homebrew/Cellar/python@3.13/3.13.7/Frameworks/Python.framework/Versions/3.13/lib/python3.13/concurrent/futures/thread.py", line 59, in run
    result = self.fn(*self.args, **self.kwargs)
  File "/opt/homebrew/Cellar/python@3.13/3.13.7/Frameworks/Python.framework/Versions/3.13/lib/python3.13/socket.py", line 977, in getaddrinfo
    for res in _socket.getaddrinfo(host, port, family, type, proto, flags):
               ~~~~~~~~~~~~~~~~~~~^^^^^^^^^^^^^^^^^^^^^^^^^^^^^^^^^^^^^^^^
socket.gaierror: [Errno 8] nodename nor servname provided, or not known
